Workbook

Sheet Proyección 36 Meses
A1: VARIABLES GLOBALES
A2: Usuarios Nuevos por Mes | B2: 50
A3: Monto Recarga | B3: 125
A4: Comisión por Portabilidad | B4: 0.5
A5: Comisión Residual | B5: 0.1
A6: Degradación Segundo Mes (%) | B6: 0.3
A7: Degradación Mensual Posterior (%) | B7: 0.025
A9: Mes | B9: Ganancia por Activaciones (MXN) | C9: Ganancia Residual 10% (con Degradación) (MXN) | D9: Ganancia Total por Mes (MXN) | E9: Ganancia Acumulada (MXN) | F9: Usuarios Activos con Degradación
A10: 1 | B10: =$B$2*$B$3*$B$4 -> 3125 | C10: =0 -> 0 | D10: =B10+C10 -> 3125 | E10: =D10 -> 3125 | F10: =$B$2 -> 50
A11: 2 | B11: =$B$2*$B$3*$B$4 -> 3125 | C11: =(1-$B$6)*$B$2*$B$3*$B$5 -> 437.5 | D11: =B11+C11 -> 3562.5 | E11: =D11+E10 -> 6687.5 | F11: =$B$2+(1-$B$6)*$B$2 -> 85
A12: 3 | B12: =$B$2*$B$3*$B$4 -> 3125 | C12: =(1-$B$6)*(1-$B$7)^1*$B$2*$B$3*$B$5+(1-$B$6)*$B$2*$B$3*$B$5 -> 864.0625 | D12: =B12+C12 -> 3989.0625 | E12: =D12+E11 -> 10676.562 | F12: =$B$2+(1-$B$6)*(1-$B$7)^1*$B$2+(1-$B$6)*$B$2 -> 119.125
A13: 4 | B13: =$B$2*$B$3*$B$4 -> 3125 | C13: =(1-$B$6)*(1-$B$7)^2*$B$2*$B$3*$B$5+(1-$B$6)*(1-$B$7)^1*$B$2*$B$3*$B$5+(1-$B$6)*$B$2*$B$3*$B$5 -> 1279.9609 | D13: =B13+C13 -> 4404.9609 | E13: =D13+E12 -> 15081.523 | F13: =$B$2+(1-$B$6)*(1-$B$7)^2*$B$2+(1-$B$6)*(1-$B$7)^1*$B$2+(1-$B$6)*$B$2 -> 152.39687
A14: 5 | B14: =$B$2*$B$3*$B$4 -> 3125 | C14: =(1-$B$6)*(1-$B$7)^3*$B$2*$B$3*$B$5+(1-$B$6)*(1-$B$7)^2*$B$2*$B$3*$B$5+(1-$B$6)*(1-$B$7)^1*$B$2*$B$3*$B$5+(1-$B$6)*$B$2*$B$3*$B$5 -> 1685.4619 | D14: =B14+C14 -> 4810.4619 | E14: =D14+E13 -> 19891.985 | F14: =$B$2+(1-$B$6)*(1-$B$7)^3*$B$2+(1-$B$6)*(1-$B$7)^2*$B$2+(1-$B$6)*(1-$B$7)^1*$B$2+(1-$B$6)*$B$2 -> 184.83695
A15: 6 | B15: =$B$2*$B$3*$B$4 -> 3125 | C15: =(1-$B$6)*(1-$B$7)^4*$B$2*$B$3*$B$5+(1-$B$6)*(1-$B$7)^3*$B$2*$B$3*$B$5+(1-$B$6)*(1-$B$7)^2*$B$2*$B$3*$B$5+(1-$B$6)*(1-$B$7)^1*$B$2*$B$3*$B$5+(1-$B$6)*$B$2*$B$3*$B$5 -> 2080.8254 | D15: =B15+C15 -> 5205.8254 | E15: =D15+E14 -> 25097.811 | F15: =$B$2+(1-$B$6)*(1-$B$7)^4*$B$2+(1-$B$6)*(1-$B$7)^3*$B$2+(1-$B$6)*(1-$B$7)^2*$B$2+(1-$B$6)*(1-$B$7)^1*$B$2+(1-$B$6)*$B$2 -> 216.46603
A16: 7 | B16: =$B$2*$B$3*$B$4 -> 3125 | C16: =(1-$B$6)*(1-$B$7)^5*$B$2*$B$3*$B$5+(1-$B$6)*(1-$B$7)^4*$B$2*$B$3*$B$5+(1-$B$6)*(1-$B$7)^3*$B$2*$B$3*$B$5+(1-$B$6)*(1-$B$7)^2*$B$2*$B$3*$B$5+(1-$B$6)*(1-$B$7)^1*$B$2*$B$3*$B$5+(1-$B$6)*$B$2*$B$3*$B$5 -> 2466.3047 | D16: =B16+C16 -> 5591.3047 | E16: =D16+E15 -> 30689.115 | F16: =$B$2+(1-$B$6)*(1-$B$7)^5*$B$2+(1-$B$6)*(1-$B$7)^4*$B$2+(1-$B$6)*(1-$B$7)^3*$B$2+(1-$B$6)*(1-$B$7)^2*$B$2+(1-$B$6)*(1-$B$7)^1*$B$2+(1-$B$6)*$B$2 -> 247.30438
A17: 8 | B17: =$B$2*$B$3*$B$4 -> 3125 | C17: =(1-$B$6)*(1-$B$7)^6*$B$2*$B$3*$B$5+(1-$B$6)*(1-$B$7)^5*$B$2*$B$3*$B$5+(1-$B$6)*(1-$B$7)^4*$B$2*$B$3*$B$5+(1-$B$6)*(1-$B$7)^3*$B$2*$B$3*$B$5+(1-$B$6)*(1-$B$7)^2*$B$2*$B$3*$B$5+(1-$B$6)*(1-$B$7)^1*$B$2*$B$3*$B$5+(1-$B$6)*$B$2*$B$3*$B$5 -> 2842.1471 | D17: =B17+C17 -> 5967.1471 | E17: =D17+E16 -> 36656.263 | F17: =$B$2+(1-$B$6)*(1-$B$7)^6*$B$2+(1-$B$6)*(1-$B$7)^5*$B$2+(1-$B$6)*(1-$B$7)^4*$B$2+(1-$B$6)*(1-$B$7)^3*$B$2+(1-$B$6)*(1-$B$7)^2*$B$2+(1-$B$6)*(1-$B$7)^1*$B$2+(1-$B$6)*$B$2 -> 277.37177
A18: 9 | B18: =$B$2*$B$3*$B$4 -> 3125 | C18: =(1-$B$6)*(1-$B$7)^7*$B$2*$B$3*$B$5+(1-$B$6)*(1-$B$7)^6*$B$2*$B$3*$B$5+(1-$B$6)*(1-$B$7)^5*$B$2*$B$3*$B$5+(1-$B$6)*(1-$B$7)^4*$B$2*$B$3*$B$5+(1-$B$6)*(1-$B$7)^3*$B$2*$B$3*$B$5+(1-$B$6)*(1-$B$7)^2*$B$2*$B$3*$B$5+(1-$B$6)*(1-$B$7)^1*$B$2*$B$3*$B$5+(1-$B$6)*$B$2*$B$3*$B$5 -> 3208.5934 | D18: =B18+C18 -> 6333.5934 | E18: =D18+E17 -> 42989.856 | F18: =$B$2+(1-$B$6)*(1-$B$7)^7*$B$2+(1-$B$6)*(1-$B$7)^6*$B$2+(1-$B$6)*(1-$B$7)^5*$B$2+(1-$B$6)*(1-$B$7)^4*$B$2+(1-$B$6)*(1-$B$7)^3*$B$2+(1-$B$6)*(1-$B$7)^2*$B$2+(1-$B$6)*(1-$B$7)^1*$B$2+(1-$B$6)*$B$2 -> 306.68747
A19: 10 | B19: =$B$2*$B$3*$B$4 -> 3125 | C19: =(1-$B$6)*(1-$B$7)^8*$B$2*$B$3*$B$5+(1-$B$6)*(1-$B$7)^7*$B$2*$B$3*$B$5+(1-$B$6)*(1-$B$7)^6*$B$2*$B$3*$B$5+(1-$B$6)*(1-$B$7)^5*$B$2*$B$3*$B$5+(1-$B$6)*(1-$B$7)^4*$B$2*$B$3*$B$5+(1-$B$6)*(1-$B$7)^3*$B$2*$B$3*$B$5+(1-$B$6)*(1-$B$7)^2*$B$2*$B$3*$B$5+(1-$B$6)*(1-$B$7)^1*$B$2*$B$3*$B$5+(1-$B$6)*$B$2*$B$3*$B$5 -> 3565.8786 | D19: =B19+C19 -> 6690.8786 | E19: =D19+E18 -> 49680.735 | F19: =$B$2+(1-$B$6)*(1-$B$7)^8*$B$2+(1-$B$6)*(1-$B$7)^7*$B$2+(1-$B$6)*(1-$B$7)^6*$B$2+(1-$B$6)*(1-$B$7)^5*$B$2+(1-$B$6)*(1-$B$7)^4*$B$2+(1-$B$6)*(1-$B$7)^3*$B$2+(1-$B$6)*(1-$B$7)^2*$B$2+(1-$B$6)*(1-$B$7)^1*$B$2+(1-$B$6)*$B$2 -> 335.27029
A20: 11 | B20: =$B$2*$B$3*$B$4 -> 3125 | C20: =(1-$B$6)*(1-$B$7)^9*$B$2*$B$3*$B$5+(1-$B$6)*(1-$B$7)^8*$B$2*$B$3*$B$5+(1-$B$6)*(1-$B$7)^7*$B$2*$B$3*$B$5+(1-$B$6)*(1-$B$7)^6*$B$2*$B$3*$B$5+(1-$B$6)*(1-$B$7)^5*$B$2*$B$3*$B$5+(1-$B$6)*(1-$B$7)^4*$B$2*$B$3*$B$5+(1-$B$6)*(1-$B$7)^3*$B$2*$B$3*$B$5+(1-$B$6)*(1-$B$7)^2*$B$2*$B$3*$B$5+(1-$B$6)*(1-$B$7)^1*$B$2*$B$3*$B$5+(1-$B$6)*$B$2*$B$3*$B$5 -> 3914.2316 | D20: =B20+C20 -> 7039.2316 | E20: =D20+E19 -> 56719.966 | F20: =$B$2+(1-$B$6)*(1-$B$7)^9*$B$2+(1-$B$6)*(1-$B$7)^8*$B$2+(1-$B$6)*(1-$B$7)^7*$B$2+(1-$B$6)*(1-$B$7)^6*$B$2+(1-$B$6)*(1-$B$7)^5*$B$2+(1-$B$6)*(1-$B$7)^4*$B$2+(1-$B$6)*(1-$B$7)^3*$B$2+(1-$B$6)*(1-$B$7)^2*$B$2+(1-$B$6)*(1-$B$7)^1*$B$2+(1-$B$6)*$B$2 -> 363.13853
A21: 12 | B21: =$B$2*$B$3*$B$4 -> 3125 | C21: =(1-$B$6)*(1-$B$7)^10*$B$2*$B$3*$B$5+(1-$B$6)*(1-$B$7)^9*$B$2*$B$3*$B$5+(1-$B$6)*(1-$B$7)^8*$B$2*$B$3*$B$5+(1-$B$6)*(1-$B$7)^7*$B$2*$B$3*$B$5+(1-$B$6)*(1-$B$7)^6*$B$2*$B$3*$B$5+(1-$B$6)*(1-$B$7)^5*$B$2*$B$3*$B$5+(1-$B$6)*(1-$B$7)^4*$B$2*$B$3*$B$5+(1-$B$6)*(1-$B$7)^3*$B$2*$B$3*$B$5+(1-$B$6)*(1-$B$7)^2*$B$2*$B$3*$B$5+(1-$B$6)*(1-$B$7)^1*$B$2*$B$3*$B$5+(1-$B$6)*$B$2*$B$3*$B$5 -> 4253.8758 | D21: =B21+C21 -> 7378.8758 | E21: =D21+E20 -> 64098.842 | F21: =$B$2+(1-$B$6)*(1-$B$7)^10*$B$2+(1-$B$6)*(1-$B$7)^9*$B$2+(1-$B$6)*(1-$B$7)^8*$B$2+(1-$B$6)*(1-$B$7)^7*$B$2+(1-$B$6)*(1-$B$7)^6*$B$2+(1-$B$6)*(1-$B$7)^5*$B$2+(1-$B$6)*(1-$B$7)^4*$B$2+(1-$B$6)*(1-$B$7)^3*$B$2+(1-$B$6)*(1-$B$7)^2*$B$2+(1-$B$6)*(1-$B$7)^1*$B$2+(1-$B$6)*$B$2 -> 390.31007
A22: 13 | B22: =$B$2*$B$3*$B$4 -> 3125 | C22: =(1-$B$6)*(1-$B$7)^11*$B$2*$B$3*$B$5+(1-$B$6)*(1-$B$7)^10*$B$2*$B$3*$B$5+(1-$B$6)*(1-$B$7)^9*$B$2*$B$3*$B$5+(1-$B$6)*(1-$B$7)^8*$B$2*$B$3*$B$5+(1-$B$6)*(1-$B$7)^7*$B$2*$B$3*$B$5+(1-$B$6)*(1-$B$7)^6*$B$2*$B$3*$B$5+(1-$B$6)*(1-$B$7)^5*$B$2*$B$3*$B$5+(1-$B$6)*(1-$B$7)^4*$B$2*$B$3*$B$5+(1-$B$6)*(1-$B$7)^3*$B$2*$B$3*$B$5+(1-$B$6)*(1-$B$7)^2*$B$2*$B$3*$B$5+(1-$B$6)*(1-$B$7)^1*$B$2*$B$3*$B$5+(1-$B$6)*$B$2*$B$3*$B$5 -> 4585.0289 | D22: =B22+C22 -> 7710.0289 | E22: =D22+E21 -> 71808.871 | F22: =$B$2+(1-$B$6)*(1-$B$7)^11*$B$2+(1-$B$6)*(1-$B$7)^10*$B$2+(1-$B$6)*(1-$B$7)^9*$B$2+(1-$B$6)*(1-$B$7)^8*$B$2+(1-$B$6)*(1-$B$7)^7*$B$2+(1-$B$6)*(1-$B$7)^6*$B$2+(1-$B$6)*(1-$B$7)^5*$B$2+(1-$B$6)*(1-$B$7)^4*$B$2+(1-$B$6)*(1-$B$7)^3*$B$2+(1-$B$6)*(1-$B$7)^2*$B$2+(1-$B$6)*(1-$B$7)^1*$B$2+(1-$B$6)*$B$2 -> 416.80232
A23: 14 | B23: =$B$2*$B$3*$B$4 -> 3125 | C23: =(1-$B$6)*(1-$B$7)^12*$B$2*$B$3*$B$5+(1-$B$6)*(1-$B$7)^11*$B$2*$B$3*$B$5+(1-$B$6)*(1-$B$7)^10*$B$2*$B$3*$B$5+(1-$B$6)*(1-$B$7)^9*$B$2*$B$3*$B$5+(1-$B$6)*(1-$B$7)^8*$B$2*$B$3*$B$5+(1-$B$6)*(1-$B$7)^7*$B$2*$B$3*$B$5+(1-$B$6)*(1-$B$7)^6*$B$2*$B$3*$B$5+(1-$B$6)*(1-$B$7)^5*$B$2*$B$3*$B$5+(1-$B$6)*(1-$B$7)^4*$B$2*$B$3*$B$5+(1-$B$6)*(1-$B$7)^3*$B$2*$B$3*$B$5+(1-$B$6)*(1-$B$7)^2*$B$2*$B$3*$B$5+(1-$B$6)*(1-$B$7)^1*$B$2*$B$3*$B$5+(1-$B$6)*$B$2*$B$3*$B$5 -> 4907.9032 | D23: =B23+C23 -> 8032.9032 | E23: =D23+E22 -> 79841.774 | F23: =$B$2+(1-$B$6)*(1-$B$7)^12*$B$2+(1-$B$6)*(1-$B$7)^11*$B$2+(1-$B$6)*(1-$B$7)^10*$B$2+(1-$B$6)*(1-$B$7)^9*$B$2+(1-$B$6)*(1-$B$7)^8*$B$2+(1-$B$6)*(1-$B$7)^7*$B$2+(1-$B$6)*(1-$B$7)^6*$B$2+(1-$B$6)*(1-$B$7)^5*$B$2+(1-$B$6)*(1-$B$7)^4*$B$2+(1-$B$6)*(1-$B$7)^3*$B$2+(1-$B$6)*(1-$B$7)^2*$B$2+(1-$B$6)*(1-$B$7)^1*$B$2+(1-$B$6)*$B$2 -> 442.63226
A24: 15 | B24: =$B$2*$B$3*$B$4 -> 3125 | C24: =(1-$B$6)*(1-$B$7)^13*$B$2*$B$3*$B$5+(1-$B$6)*(1-$B$7)^12*$B$2*$B$3*$B$5+(1-$B$6)*(1-$B$7)^11*$B$2*$B$3*$B$5+(1-$B$6)*(1-$B$7)^10*$B$2*$B$3*$B$5+(1-$B$6)*(1-$B$7)^9*$B$2*$B$3*$B$5+(1-$B$6)*(1-$B$7)^8*$B$2*$B$3*$B$5+(1-$B$6)*(1-$B$7)^7*$B$2*$B$3*$B$5+(1-$B$6)*(1-$B$7)^6*$B$2*$B$3*$B$5+(1-$B$6)*(1-$B$7)^5*$B$2*$B$3*$B$5+(1-$B$6)*(1-$B$7)^4*$B$2*$B$3*$B$5+(1-$B$6)*(1-$B$7)^3*$B$2*$B$3*$B$5+(1-$B$6)*(1-$B$7)^2*$B$2*$B$3*$B$5+(1-$B$6)*(1-$B$7)^1*$B$2*$B$3*$B$5+(1-$B$6)*$B$2*$B$3*$B$5 -> 5222.7056 | D24: =B24+C24 -> 8347.7056 | E24: =D24+E23 -> 88189.48 | F24: =$B$2+(1-$B$6)*(1-$B$7)^13*$B$2+(1-$B$6)*(1-$B$7)^12*$B$2+(1-$B$6)*(1-$B$7)^11*$B$2+(1-$B$6)*(1-$B$7)^10*$B$2+(1-$B$6)*(1-$B$7)^9*$B$2+(1-$B$6)*(1-$B$7)^8*$B$2+(1-$B$6)*(1-$B$7)^7*$B$2+(1-$B$6)*(1-$B$7)^6*$B$2+(1-$B$6)*(1-$B$7)^5*$B$2+(1-$B$6)*(1-$B$7)^4*$B$2+(1-$B$6)*(1-$B$7)^3*$B$2+(1-$B$6)*(1-$B$7)^2*$B$2+(1-$B$6)*(1-$B$7)^1*$B$2+(1-$B$6)*$B$2 -> 467.81645
A25: 16 | B25: =$B$2*$B$3*$B$4 -> 3125 | C25: =(1-$B$6)*(1-$B$7)^14*$B$2*$B$3*$B$5+(1-$B$6)*(1-$B$7)^13*$B$2*$B$3*$B$5+(1-$B$6)*(1-$B$7)^12*$B$2*$B$3*$B$5+(1-$B$6)*(1-$B$7)^11*$B$2*$B$3*$B$5+(1-$B$6)*(1-$B$7)^10*$B$2*$B$3*$B$5+(1-$B$6)*(1-$B$7)^9*$B$2*$B$3*$B$5+(1-$B$6)*(1-$B$7)^8*$B$2*$B$3*$B$5+(1-$B$6)*(1-$B$7)^7*$B$2*$B$3*$B$5+(1-$B$6)*(1-$B$7)^6*$B$2*$B$3*$B$5+(1-$B$6)*(1-$B$7)^5*$B$2*$B$3*$B$5+(1-$B$6)*(1-$B$7)^4*$B$2*$B$3*$B$5+(1-$B$6)*(1-$B$7)^3*$B$2*$B$3*$B$5+(1-$B$6)*(1-$B$7)^2*$B$2*$B$3*$B$5+(1-$B$6)*(1-$B$7)^1*$B$2*$B$3*$B$5+(1-$B$6)*$B$2*$B$3*$B$5 -> 5529.638 | D25: =B25+C25 -> 8654.638 | E25: =D25+E24 -> 96844.118 | F25: =$B$2+(1-$B$6)*(1-$B$7)^14*$B$2+(1-$B$6)*(1-$B$7)^13*$B$2+(1-$B$6)*(1-$B$7)^12*$B$2+(1-$B$6)*(1-$B$7)^11*$B$2+(1-$B$6)*(1-$B$7)^10*$B$2+(1-$B$6)*(1-$B$7)^9*$B$2+(1-$B$6)*(1-$B$7)^8*$B$2+(1-$B$6)*(1-$B$7)^7*$B$2+(1-$B$6)*(1-$B$7)^6*$B$2+(1-$B$6)*(1-$B$7)^5*$B$2+(1-$B$6)*(1-$B$7)^4*$B$2+(1-$B$6)*(1-$B$7)^3*$B$2+(1-$B$6)*(1-$B$7)^2*$B$2+(1-$B$6)*(1-$B$7)^1*$B$2+(1-$B$6)*$B$2 -> 492.37104
A26: 17 | B26: =$B$2*$B$3*$B$4 -> 3125 | C26: =(1-$B$6)*(1-$B$7)^15*$B$2*$B$3*$B$5+(1-$B$6)*(1-$B$7)^14*$B$2*$B$3*$B$5+(1-$B$6)*(1-$B$7)^13*$B$2*$B$3*$B$5+(1-$B$6)*(1-$B$7)^12*$B$2*$B$3*$B$5+(1-$B$6)*(1-$B$7)^11*$B$2*$B$3*$B$5+(1-$B$6)*(1-$B$7)^10*$B$2*$B$3*$B$5+(1-$B$6)*(1-$B$7)^9*$B$2*$B$3*$B$5+(1-$B$6)*(1-$B$7)^8*$B$2*$B$3*$B$5+(1-$B$6)*(1-$B$7)^7*$B$2*$B$3*$B$5+(1-$B$6)*(1-$B$7)^6*$B$2*$B$3*$B$5+(1-$B$6)*(1-$B$7)^5*$B$2*$B$3*$B$5+(1-$B$6)*(1-$B$7)^4*$B$2*$B$3*$B$5+(1-$B$6)*(1-$B$7)^3*$B$2*$B$3*$B$5+(1-$B$6)*(1-$B$7)^2*$B$2*$B$3*$B$5+(1-$B$6)*(1-$B$7)^1*$B$2*$B$3*$B$5+(1-$B$6)*$B$2*$B$3*$B$5 -> 5828.8971 | D26: =B26+C26 -> 8953.8971 | E26: =D26+E25 -> 105798.01 | F26: =$B$2+(1-$B$6)*(1-$B$7)^15*$B$2+(1-$B$6)*(1-$B$7)^14*$B$2+(1-$B$6)*(1-$B$7)^13*$B$2+(1-$B$6)*(1-$B$7)^12*$B$2+(1-$B$6)*(1-$B$7)^11*$B$2+(1-$B$6)*(1-$B$7)^10*$B$2+(1-$B$6)*(1-$B$7)^9*$B$2+(1-$B$6)*(1-$B$7)^8*$B$2+(1-$B$6)*(1-$B$7)^7*$B$2+(1-$B$6)*(1-$B$7)^6*$B$2+(1-$B$6)*(1-$B$7)^5*$B$2+(1-$B$6)*(1-$B$7)^4*$B$2+(1-$B$6)*(1-$B$7)^3*$B$2+(1-$B$6)*(1-$B$7)^2*$B$2+(1-$B$6)*(1-$B$7)^1*$B$2+(1-$B$6)*$B$2 -> 516.31176
A27: 18 | B27: =$B$2*$B$3*$B$4 -> 3125 | C27: =(1-$B$6)*(1-$B$7)^16*$B$2*$B$3*$B$5+(1-$B$6)*(1-$B$7)^15*$B$2*$B$3*$B$5+(1-$B$6)*(1-$B$7)^14*$B$2*$B$3*$B$5+(1-$B$6)*(1-$B$7)^13*$B$2*$B$3*$B$5+(1-$B$6)*(1-$B$7)^12*$B$2*$B$3*$B$5+(1-$B$6)*(1-$B$7)^11*$B$2*$B$3*$B$5+(1-$B$6)*(1-$B$7)^10*$B$2*$B$3*$B$5+(1-$B$6)*(1-$B$7)^9*$B$2*$B$3*$B$5+(1-$B$6)*(1-$B$7)^8*$B$2*$B$3*$B$5+(1-$B$6)*(1-$B$7)^7*$B$2*$B$3*$B$5+(1-$B$6)*(1-$B$7)^6*$B$2*$B$3*$B$5+(1-$B$6)*(1-$B$7)^5*$B$2*$B$3*$B$5+(1-$B$6)*(1-$B$7)^4*$B$2*$B$3*$B$5+(1-$B$6)*(1-$B$7)^3*$B$2*$B$3*$B$5+(1-$B$6)*(1-$B$7)^2*$B$2*$B$3*$B$5+(1-$B$6)*(1-$B$7)^1*$B$2*$B$3*$B$5+(1-$B$6)*$B$2*$B$3*$B$5 -> 6120.6746 | D27: =B27+C27 -> 9245.6746 | E27: =D27+E26 -> 115043.69 | F27: =$B$2+(1-$B$6)*(1-$B$7)^16*$B$2+(1-$B$6)*(1-$B$7)^15*$B$2+(1-$B$6)*(1-$B$7)^14*$B$2+(1-$B$6)*(1-$B$7)^13*$B$2+(1-$B$6)*(1-$B$7)^12*$B$2+(1-$B$6)*(1-$B$7)^11*$B$2+(1-$B$6)*(1-$B$7)^10*$B$2+(1-$B$6)*(1-$B$7)^9*$B$2+(1-$B$6)*(1-$B$7)^8*$B$2+(1-$B$6)*(1-$B$7)^7*$B$2+(1-$B$6)*(1-$B$7)^6*$B$2+(1-$B$6)*(1-$B$7)^5*$B$2+(1-$B$6)*(1-$B$7)^4*$B$2+(1-$B$6)*(1-$B$7)^3*$B$2+(1-$B$6)*(1-$B$7)^2*$B$2+(1-$B$6)*(1-$B$7)^1*$B$2+(1-$B$6)*$B$2 -> 539.65397
A28: 19 | B28: =$B$2*$B$3*$B$4 -> 3125 | C28: =(1-$B$6)*(1-$B$7)^17*$B$2*$B$3*$B$5+(1-$B$6)*(1-$B$7)^16*$B$2*$B$3*$B$5+(1-$B$6)*(1-$B$7)^15*$B$2*$B$3*$B$5+(1-$B$6)*(1-$B$7)^14*$B$2*$B$3*$B$5+(1-$B$6)*(1-$B$7)^13*$B$2*$B$3*$B$5+(1-$B$6)*(1-$B$7)^12*$B$2*$B$3*$B$5+(1-$B$6)*(1-$B$7)^11*$B$2*$B$3*$B$5+(1-$B$6)*(1-$B$7)^10*$B$2*$B$3*$B$5+(1-$B$6)*(1-$B$7)^9*$B$2*$B$3*$B$5+(1-$B$6)*(1-$B$7)^8*$B$2*$B$3*$B$5+(1-$B$6)*(1-$B$7)^7*$B$2*$B$3*$B$5+(1-$B$6)*(1-$B$7)^6*$B$2*$B$3*$B$5+(1-$B$6)*(1-$B$7)^5*$B$2*$B$3*$B$5+(1-$B$6)*(1-$B$7)^4*$B$2*$B$3*$B$5+(1-$B$6)*(1-$B$7)^3*$B$2*$B$3*$B$5+(1-$B$6)*(1-$B$7)^2*$B$2*$B$3*$B$5+(1-$B$6)*(1-$B$7)^1*$B$2*$B$3*$B$5+(1-$B$6)*$B$2*$B$3*$B$5 -> 6405.1578 | D28: =B28+C28 -> 9530.1578 | E28: =D28+E27 -> 124573.85 | F28: =$B$2+(1-$B$6)*(1-$B$7)^17*$B$2+(1-$B$6)*(1-$B$7)^16*$B$2+(1-$B$6)*(1-$B$7)^15*$B$2+(1-$B$6)*(1-$B$7)^14*$B$2+(1-$B$6)*(1-$B$7)^13*$B$2+(1-$B$6)*(1-$B$7)^12*$B$2+(1-$B$6)*(1-$B$7)^11*$B$2+(1-$B$6)*(1-$B$7)^10*$B$2+(1-$B$6)*(1-$B$7)^9*$B$2+(1-$B$6)*(1-$B$7)^8*$B$2+(1-$B$6)*(1-$B$7)^7*$B$2+(1-$B$6)*(1-$B$7)^6*$B$2+(1-$B$6)*(1-$B$7)^5*$B$2+(1-$B$6)*(1-$B$7)^4*$B$2+(1-$B$6)*(1-$B$7)^3*$B$2+(1-$B$6)*(1-$B$7)^2*$B$2+(1-$B$6)*(1-$B$7)^1*$B$2+(1-$B$6)*$B$2 -> 562.41262
A29: 20 | B29: =$B$2*$B$3*$B$4 -> 3125 | C29: =(1-$B$6)*(1-$B$7)^18*$B$2*$B$3*$B$5+(1-$B$6)*(1-$B$7)^17*$B$2*$B$3*$B$5+(1-$B$6)*(1-$B$7)^16*$B$2*$B$3*$B$5+(1-$B$6)*(1-$B$7)^15*$B$2*$B$3*$B$5+(1-$B$6)*(1-$B$7)^14*$B$2*$B$3*$B$5+(1-$B$6)*(1-$B$7)^13*$B$2*$B$3*$B$5+(1-$B$6)*(1-$B$7)^12*$B$2*$B$3*$B$5+(1-$B$6)*(1-$B$7)^11*$B$2*$B$3*$B$5+(1-$B$6)*(1-$B$7)^10*$B$2*$B$3*$B$5+(1-$B$6)*(1-$B$7)^9*$B$2*$B$3*$B$5+(1-$B$6)*(1-$B$7)^8*$B$2*$B$3*$B$5+(1-$B$6)*(1-$B$7)^7*$B$2*$B$3*$B$5+(1-$B$6)*(1-$B$7)^6*$B$2*$B$3*$B$5+(1-$B$6)*(1-$B$7)^5*$B$2*$B$3*$B$5+(1-$B$6)*(1-$B$7)^4*$B$2*$B$3*$B$5+(1-$B$6)*(1-$B$7)^3*$B$2*$B$3*$B$5+(1-$B$6)*(1-$B$7)^2*$B$2*$B$3*$B$5+(1-$B$6)*(1-$B$7)^1*$B$2*$B$3*$B$5+(1-$B$6)*$B$2*$B$3*$B$5 -> 6682.5288 | D29: =B29+C29 -> 9807.5288 | E29: =D29+E28 -> 134381.38 | F29: =$B$2+(1-$B$6)*(1-$B$7)^18*$B$2+(1-$B$6)*(1-$B$7)^17*$B$2+(1-$B$6)*(1-$B$7)^16*$B$2+(1-$B$6)*(1-$B$7)^15*$B$2+(1-$B$6)*(1-$B$7)^14*$B$2+(1-$B$6)*(1-$B$7)^13*$B$2+(1-$B$6)*(1-$B$7)^12*$B$2+(1-$B$6)*(1-$B$7)^11*$B$2+(1-$B$6)*(1-$B$7)^10*$B$2+(1-$B$6)*(1-$B$7)^9*$B$2+(1-$B$6)*(1-$B$7)^8*$B$2+(1-$B$6)*(1-$B$7)^7*$B$2+(1-$B$6)*(1-$B$7)^6*$B$2+(1-$B$6)*(1-$B$7)^5*$B$2+(1-$B$6)*(1-$B$7)^4*$B$2+(1-$B$6)*(1-$B$7)^3*$B$2+(1-$B$6)*(1-$B$7)^2*$B$2+(1-$B$6)*(1-$B$7)^1*$B$2+(1-$B$6)*$B$2 -> 584.60231
A30: 21 | B30: =$B$2*$B$3*$B$4 -> 3125 | C30: =(1-$B$6)*(1-$B$7)^19*$B$2*$B$3*$B$5+(1-$B$6)*(1-$B$7)^18*$B$2*$B$3*$B$5+(1-$B$6)*(1-$B$7)^17*$B$2*$B$3*$B$5+(1-$B$6)*(1-$B$7)^16*$B$2*$B$3*$B$5+(1-$B$6)*(1-$B$7)^15*$B$2*$B$3*$B$5+(1-$B$6)*(1-$B$7)^14*$B$2*$B$3*$B$5+(1-$B$6)*(1-$B$7)^13*$B$2*$B$3*$B$5+(1-$B$6)*(1-$B$7)^12*$B$2*$B$3*$B$5+(1-$B$6)*(1-$B$7)^11*$B$2*$B$3*$B$5+(1-$B$6)*(1-$B$7)^10*$B$2*$B$3*$B$5+(1-$B$6)*(1-$B$7)^9*$B$2*$B$3*$B$5+(1-$B$6)*(1-$B$7)^8*$B$2*$B$3*$B$5+(1-$B$6)*(1-$B$7)^7*$B$2*$B$3*$B$5+(1-$B$6)*(1-$B$7)^6*$B$2*$B$3*$B$5+(1-$B$6)*(1-$B$7)^5*$B$2*$B$3*$B$5+(1-$B$6)*(1-$B$7)^4*$B$2*$B$3*$B$5+(1-$B$6)*(1-$B$7)^3*$B$2*$B$3*$B$5+(1-$B$6)*(1-$B$7)^2*$B$2*$B$3*$B$5+(1-$B$6)*(1-$B$7)^1*$B$2*$B$3*$B$5+(1-$B$6)*$B$2*$B$3*$B$5 -> 6952.9656 | D30: =B30+C30 -> 10077.966 | E30: =D30+E29 -> 144459.34 | F30: =$B$2+(1-$B$6)*(1-$B$7)^19*$B$2+(1-$B$6)*(1-$B$7)^18*$B$2+(1-$B$6)*(1-$B$7)^17*$B$2+(1-$B$6)*(1-$B$7)^16*$B$2+(1-$B$6)*(1-$B$7)^15*$B$2+(1-$B$6)*(1-$B$7)^14*$B$2+(1-$B$6)*(1-$B$7)^13*$B$2+(1-$B$6)*(1-$B$7)^12*$B$2+(1-$B$6)*(1-$B$7)^11*$B$2+(1-$B$6)*(1-$B$7)^10*$B$2+(1-$B$6)*(1-$B$7)^9*$B$2+(1-$B$6)*(1-$B$7)^8*$B$2+(1-$B$6)*(1-$B$7)^7*$B$2+(1-$B$6)*(1-$B$7)^6*$B$2+(1-$B$6)*(1-$B$7)^5*$B$2+(1-$B$6)*(1-$B$7)^4*$B$2+(1-$B$6)*(1-$B$7)^3*$B$2+(1-$B$6)*(1-$B$7)^2*$B$2+(1-$B$6)*(1-$B$7)^1*$B$2+(1-$B$6)*$B$2 -> 606.23725
A31: 22 | B31: =$B$2*$B$3*$B$4 -> 3125 | C31: =(1-$B$6)*(1-$B$7)^20*$B$2*$B$3*$B$5+(1-$B$6)*(1-$B$7)^19*$B$2*$B$3*$B$5+(1-$B$6)*(1-$B$7)^18*$B$2*$B$3*$B$5+(1-$B$6)*(1-$B$7)^17*$B$2*$B$3*$B$5+(1-$B$6)*(1-$B$7)^16*$B$2*$B$3*$B$5+(1-$B$6)*(1-$B$7)^15*$B$2*$B$3*$B$5+(1-$B$6)*(1-$B$7)^14*$B$2*$B$3*$B$5+(1-$B$6)*(1-$B$7)^13*$B$2*$B$3*$B$5+(1-$B$6)*(1-$B$7)^12*$B$2*$B$3*$B$5+(1-$B$6)*(1-$B$7)^11*$B$2*$B$3*$B$5+(1-$B$6)*(1-$B$7)^10*$B$2*$B$3*$B$5+(1-$B$6)*(1-$B$7)^9*$B$2*$B$3*$B$5+(1-$B$6)*(1-$B$7)^8*$B$2*$B$3*$B$5+(1-$B$6)*(1-$B$7)^7*$B$2*$B$3*$B$5+(1-$B$6)*(1-$B$7)^6*$B$2*$B$3*$B$5+(1-$B$6)*(1-$B$7)^5*$B$2*$B$3*$B$5+(1-$B$6)*(1-$B$7)^4*$B$2*$B$3*$B$5+(1-$B$6)*(1-$B$7)^3*$B$2*$B$3*$B$5+(1-$B$6)*(1-$B$7)^2*$B$2*$B$3*$B$5+(1-$B$6)*(1-$B$7)^1*$B$2*$B$3*$B$5+(1-$B$6)*$B$2*$B$3*$B$5 -> 7216.6415 | D31: =B31+C31 -> 10341.641 | E31: =D31+E30 -> 154800.98 | F31: =$B$2+(1-$B$6)*(1-$B$7)^20*$B$2+(1-$B$6)*(1-$B$7)^19*$B$2+(1-$B$6)*(1-$B$7)^18*$B$2+(1-$B$6)*(1-$B$7)^17*$B$2+(1-$B$6)*(1-$B$7)^16*$B$2+(1-$B$6)*(1-$B$7)^15*$B$2+(1-$B$6)*(1-$B$7)^14*$B$2+(1-$B$6)*(1-$B$7)^13*$B$2+(1-$B$6)*(1-$B$7)^12*$B$2+(1-$B$6)*(1-$B$7)^11*$B$2+(1-$B$6)*(1-$B$7)^10*$B$2+(1-$B$6)*(1-$B$7)^9*$B$2+(1-$B$6)*(1-$B$7)^8*$B$2+(1-$B$6)*(1-$B$7)^7*$B$2+(1-$B$6)*(1-$B$7)^6*$B$2+(1-$B$6)*(1-$B$7)^5*$B$2+(1-$B$6)*(1-$B$7)^4*$B$2+(1-$B$6)*(1-$B$7)^3*$B$2+(1-$B$6)*(1-$B$7)^2*$B$2+(1-$B$6)*(1-$B$7)^1*$B$2+(1-$B$6)*$B$2 -> 627.33132
A32: 23 | B32: =$B$2*$B$3*$B$4 -> 3125 | C32: =(1-$B$6)*(1-$B$7)^21*$B$2*$B$3*$B$5+(1-$B$6)*(1-$B$7)^20*$B$2*$B$3*$B$5+(1-$B$6)*(1-$B$7)^19*$B$2*$B$3*$B$5+(1-$B$6)*(1-$B$7)^18*$B$2*$B$3*$B$5+(1-$B$6)*(1-$B$7)^17*$B$2*$B$3*$B$5+(1-$B$6)*(1-$B$7)^16*$B$2*$B$3*$B$5+(1-$B$6)*(1-$B$7)^15*$B$2*$B$3*$B$5+(1-$B$6)*(1-$B$7)^14*$B$2*$B$3*$B$5+(1-$B$6)*(1-$B$7)^13*$B$2*$B$3*$B$5+(1-$B$6)*(1-$B$7)^12*$B$2*$B$3*$B$5+(1-$B$6)*(1-$B$7)^11*$B$2*$B$3*$B$5+(1-$B$6)*(1-$B$7)^10*$B$2*$B$3*$B$5+(1-$B$6)*(1-$B$7)^9*$B$2*$B$3*$B$5+(1-$B$6)*(1-$B$7)^8*$B$2*$B$3*$B$5+(1-$B$6)*(1-$B$7)^7*$B$2*$B$3*$B$5+(1-$B$6)*(1-$B$7)^6*$B$2*$B$3*$B$5+(1-$B$6)*(1-$B$7)^5*$B$2*$B$3*$B$5+(1-$B$6)*(1-$B$7)^4*$B$2*$B$3*$B$5+(1-$B$6)*(1-$B$7)^3*$B$2*$B$3*$B$5+(1-$B$6)*(1-$B$7)^2*$B$2*$B$3*$B$5+(1-$B$6)*(1-$B$7)^1*$B$2*$B$3*$B$5+(1-$B$6)*$B$2*$B$3*$B$5 -> 7473.7254 | D32: =B32+C32 -> 10598.725 | E32: =D32+E31 -> 165399.71 | F32: =$B$2+(1-$B$6)*(1-$B$7)^21*$B$2+(1-$B$6)*(1-$B$7)^20*$B$2+(1-$B$6)*(1-$B$7)^19*$B$2+(1-$B$6)*(1-$B$7)^18*$B$2+(1-$B$6)*(1-$B$7)^17*$B$2+(1-$B$6)*(1-$B$7)^16*$B$2+(1-$B$6)*(1-$B$7)^15*$B$2+(1-$B$6)*(1-$B$7)^14*$B$2+(1-$B$6)*(1-$B$7)^13*$B$2+(1-$B$6)*(1-$B$7)^12*$B$2+(1-$B$6)*(1-$B$7)^11*$B$2+(1-$B$6)*(1-$B$7)^10*$B$2+(1-$B$6)*(1-$B$7)^9*$B$2+(1-$B$6)*(1-$B$7)^8*$B$2+(1-$B$6)*(1-$B$7)^7*$B$2+(1-$B$6)*(1-$B$7)^6*$B$2+(1-$B$6)*(1-$B$7)^5*$B$2+(1-$B$6)*(1-$B$7)^4*$B$2+(1-$B$6)*(1-$B$7)^3*$B$2+(1-$B$6)*(1-$B$7)^2*$B$2+(1-$B$6)*(1-$B$7)^1*$B$2+(1-$B$6)*$B$2 -> 647.89803
A33: 24 | B33: =$B$2*$B$3*$B$4 -> 3125 | C33: =(1-$B$6)*(1-$B$7)^22*$B$2*$B$3*$B$5+(1-$B$6)*(1-$B$7)^21*$B$2*$B$3*$B$5+(1-$B$6)*(1-$B$7)^20*$B$2*$B$3*$B$5+(1-$B$6)*(1-$B$7)^19*$B$2*$B$3*$B$5+(1-$B$6)*(1-$B$7)^18*$B$2*$B$3*$B$5+(1-$B$6)*(1-$B$7)^17*$B$2*$B$3*$B$5+(1-$B$6)*(1-$B$7)^16*$B$2*$B$3*$B$5+(1-$B$6)*(1-$B$7)^15*$B$2*$B$3*$B$5+(1-$B$6)*(1-$B$7)^14*$B$2*$B$3*$B$5+(1-$B$6)*(1-$B$7)^13*$B$2*$B$3*$B$5+(1-$B$6)*(1-$B$7)^12*$B$2*$B$3*$B$5+(1-$B$6)*(1-$B$7)^11*$B$2*$B$3*$B$5+(1-$B$6)*(1-$B$7)^10*$B$2*$B$3*$B$5+(1-$B$6)*(1-$B$7)^9*$B$2*$B$3*$B$5+(1-$B$6)*(1-$B$7)^8*$B$2*$B$3*$B$5+(1-$B$6)*(1-$B$7)^7*$B$2*$B$3*$B$5+(1-$B$6)*(1-$B$7)^6*$B$2*$B$3*$B$5+(1-$B$6)*(1-$B$7)^5*$B$2*$B$3*$B$5+(1-$B$6)*(1-$B$7)^4*$B$2*$B$3*$B$5+(1-$B$6)*(1-$B$7)^3*$B$2*$B$3*$B$5+(1-$B$6)*(1-$B$7)^2*$B$2*$B$3*$B$5+(1-$B$6)*(1-$B$7)^1*$B$2*$B$3*$B$5+(1-$B$6)*$B$2*$B$3*$B$5 -> 7724.3823 | D33: =B33+C33 -> 10849.382 | E33: =D33+E32 -> 176249.09 | F33: =$B$2+(1-$B$6)*(1-$B$7)^22*$B$2+(1-$B$6)*(1-$B$7)^21*$B$2+(1-$B$6)*(1-$B$7)^20*$B$2+(1-$B$6)*(1-$B$7)^19*$B$2+(1-$B$6)*(1-$B$7)^18*$B$2+(1-$B$6)*(1-$B$7)^17*$B$2+(1-$B$6)*(1-$B$7)^16*$B$2+(1-$B$6)*(1-$B$7)^15*$B$2+(1-$B$6)*(1-$B$7)^14*$B$2+(1-$B$6)*(1-$B$7)^13*$B$2+(1-$B$6)*(1-$B$7)^12*$B$2+(1-$B$6)*(1-$B$7)^11*$B$2+(1-$B$6)*(1-$B$7)^10*$B$2+(1-$B$6)*(1-$B$7)^9*$B$2+(1-$B$6)*(1-$B$7)^8*$B$2+(1-$B$6)*(1-$B$7)^7*$B$2+(1-$B$6)*(1-$B$7)^6*$B$2+(1-$B$6)*(1-$B$7)^5*$B$2+(1-$B$6)*(1-$B$7)^4*$B$2+(1-$B$6)*(1-$B$7)^3*$B$2+(1-$B$6)*(1-$B$7)^2*$B$2+(1-$B$6)*(1-$B$7)^1*$B$2+(1-$B$6)*$B$2 -> 667.95058
A34: 25 | B34: =$B$2*$B$3*$B$4 -> 3125 | C34: =(1-$B$6)*(1-$B$7)^23*$B$2*$B$3*$B$5+(1-$B$6)*(1-$B$7)^22*$B$2*$B$3*$B$5+(1-$B$6)*(1-$B$7)^21*$B$2*$B$3*$B$5+(1-$B$6)*(1-$B$7)^20*$B$2*$B$3*$B$5+(1-$B$6)*(1-$B$7)^19*$B$2*$B$3*$B$5+(1-$B$6)*(1-$B$7)^18*$B$2*$B$3*$B$5+(1-$B$6)*(1-$B$7)^17*$B$2*$B$3*$B$5+(1-$B$6)*(1-$B$7)^16*$B$2*$B$3*$B$5+(1-$B$6)*(1-$B$7)^15*$B$2*$B$3*$B$5+(1-$B$6)*(1-$B$7)^14*$B$2*$B$3*$B$5+(1-$B$6)*(1-$B$7)^13*$B$2*$B$3*$B$5+(1-$B$6)*(1-$B$7)^12*$B$2*$B$3*$B$5+(1-$B$6)*(1-$B$7)^11*$B$2*$B$3*$B$5+(1-$B$6)*(1-$B$7)^10*$B$2*$B$3*$B$5+(1-$B$6)*(1-$B$7)^9*$B$2*$B$3*$B$5+(1-$B$6)*(1-$B$7)^8*$B$2*$B$3*$B$5+(1-$B$6)*(1-$B$7)^7*$B$2*$B$3*$B$5+(1-$B$6)*(1-$B$7)^6*$B$2*$B$3*$B$5+(1-$B$6)*(1-$B$7)^5*$B$2*$B$3*$B$5+(1-$B$6)*(1-$B$7)^4*$B$2*$B$3*$B$5+(1-$B$6)*(1-$B$7)^3*$B$2*$B$3*$B$5+(1-$B$6)*(1-$B$7)^2*$B$2*$B$3*$B$5+(1-$B$6)*(1-$B$7)^1*$B$2*$B$3*$B$5+(1-$B$6)*$B$2*$B$3*$B$5 -> 7968.7727 | D34: =B34+C34 -> 11093.773 | E34: =D34+E33 -> 187342.86 | F34: =$B$2+(1-$B$6)*(1-$B$7)^23*$B$2+(1-$B$6)*(1-$B$7)^22*$B$2+(1-$B$6)*(1-$B$7)^21*$B$2+(1-$B$6)*(1-$B$7)^20*$B$2+(1-$B$6)*(1-$B$7)^19*$B$2+(1-$B$6)*(1-$B$7)^18*$B$2+(1-$B$6)*(1-$B$7)^17*$B$2+(1-$B$6)*(1-$B$7)^16*$B$2+(1-$B$6)*(1-$B$7)^15*$B$2+(1-$B$6)*(1-$B$7)^14*$B$2+(1-$B$6)*(1-$B$7)^13*$B$2+(1-$B$6)*(1-$B$7)^12*$B$2+(1-$B$6)*(1-$B$7)^11*$B$2+(1-$B$6)*(1-$B$7)^10*$B$2+(1-$B$6)*(1-$B$7)^9*$B$2+(1-$B$6)*(1-$B$7)^8*$B$2+(1-$B$6)*(1-$B$7)^7*$B$2+(1-$B$6)*(1-$B$7)^6*$B$2+(1-$B$6)*(1-$B$7)^5*$B$2+(1-$B$6)*(1-$B$7)^4*$B$2+(1-$B$6)*(1-$B$7)^3*$B$2+(1-$B$6)*(1-$B$7)^2*$B$2+(1-$B$6)*(1-$B$7)^1*$B$2+(1-$B$6)*$B$2 -> 687.50182
A35: 26 | B35: =$B$2*$B$3*$B$4 -> 3125 | C35: =(1-$B$6)*(1-$B$7)^24*$B$2*$B$3*$B$5+(1-$B$6)*(1-$B$7)^23*$B$2*$B$3*$B$5+(1-$B$6)*(1-$B$7)^22*$B$2*$B$3*$B$5+(1-$B$6)*(1-$B$7)^21*$B$2*$B$3*$B$5+(1-$B$6)*(1-$B$7)^20*$B$2*$B$3*$B$5+(1-$B$6)*(1-$B$7)^19*$B$2*$B$3*$B$5+(1-$B$6)*(1-$B$7)^18*$B$2*$B$3*$B$5+(1-$B$6)*(1-$B$7)^17*$B$2*$B$3*$B$5+(1-$B$6)*(1-$B$7)^16*$B$2*$B$3*$B$5+(1-$B$6)*(1-$B$7)^15*$B$2*$B$3*$B$5+(1-$B$6)*(1-$B$7)^14*$B$2*$B$3*$B$5+(1-$B$6)*(1-$B$7)^13*$B$2*$B$3*$B$5+(1-$B$6)*(1-$B$7)^12*$B$2*$B$3*$B$5+(1-$B$6)*(1-$B$7)^11*$B$2*$B$3*$B$5+(1-$B$6)*(1-$B$7)^10*$B$2*$B$3*$B$5+(1-$B$6)*(1-$B$7)^9*$B$2*$B$3*$B$5+(1-$B$6)*(1-$B$7)^8*$B$2*$B$3*$B$5+(1-$B$6)*(1-$B$7)^7*$B$2*$B$3*$B$5+(1-$B$6)*(1-$B$7)^6*$B$2*$B$3*$B$5+(1-$B$6)*(1-$B$7)^5*$B$2*$B$3*$B$5+(1-$B$6)*(1-$B$7)^4*$B$2*$B$3*$B$5+(1-$B$6)*(1-$B$7)^3*$B$2*$B$3*$B$5+(1-$B$6)*(1-$B$7)^2*$B$2*$B$3*$B$5+(1-$B$6)*(1-$B$7)^1*$B$2*$B$3*$B$5+(1-$B$6)*$B$2*$B$3*$B$5 -> 8207.0534 | D35: =B35+C35 -> 11332.053 | E35: =D35+E34 -> 198674.92 | F35: =$B$2+(1-$B$6)*(1-$B$7)^24*$B$2+(1-$B$6)*(1-$B$7)^23*$B$2+(1-$B$6)*(1-$B$7)^22*$B$2+(1-$B$6)*(1-$B$7)^21*$B$2+(1-$B$6)*(1-$B$7)^20*$B$2+(1-$B$6)*(1-$B$7)^19*$B$2+(1-$B$6)*(1-$B$7)^18*$B$2+(1-$B$6)*(1-$B$7)^17*$B$2+(1-$B$6)*(1-$B$7)^16*$B$2+(1-$B$6)*(1-$B$7)^15*$B$2+(1-$B$6)*(1-$B$7)^14*$B$2+(1-$B$6)*(1-$B$7)^13*$B$2+(1-$B$6)*(1-$B$7)^12*$B$2+(1-$B$6)*(1-$B$7)^11*$B$2+(1-$B$6)*(1-$B$7)^10*$B$2+(1-$B$6)*(1-$B$7)^9*$B$2+(1-$B$6)*(1-$B$7)^8*$B$2+(1-$B$6)*(1-$B$7)^7*$B$2+(1-$B$6)*(1-$B$7)^6*$B$2+(1-$B$6)*(1-$B$7)^5*$B$2+(1-$B$6)*(1-$B$7)^4*$B$2+(1-$B$6)*(1-$B$7)^3*$B$2+(1-$B$6)*(1-$B$7)^2*$B$2+(1-$B$6)*(1-$B$7)^1*$B$2+(1-$B$6)*$B$2 -> 706.56427
A36: 27 | B36: =$B$2*$B$3*$B$4 -> 3125 | C36: =(1-$B$6)*(1-$B$7)^25*$B$2*$B$3*$B$5+(1-$B$6)*(1-$B$7)^24*$B$2*$B$3*$B$5+(1-$B$6)*(1-$B$7)^23*$B$2*$B$3*$B$5+(1-$B$6)*(1-$B$7)^22*$B$2*$B$3*$B$5+(1-$B$6)*(1-$B$7)^21*$B$2*$B$3*$B$5+(1-$B$6)*(1-$B$7)^20*$B$2*$B$3*$B$5+(1-$B$6)*(1-$B$7)^19*$B$2*$B$3*$B$5+(1-$B$6)*(1-$B$7)^18*$B$2*$B$3*$B$5+(1-$B$6)*(1-$B$7)^17*$B$2*$B$3*$B$5+(1-$B$6)*(1-$B$7)^16*$B$2*$B$3*$B$5+(1-$B$6)*(1-$B$7)^15*$B$2*$B$3*$B$5+(1-$B$6)*(1-$B$7)^14*$B$2*$B$3*$B$5+(1-$B$6)*(1-$B$7)^13*$B$2*$B$3*$B$5+(1-$B$6)*(1-$B$7)^12*$B$2*$B$3*$B$5+(1-$B$6)*(1-$B$7)^11*$B$2*$B$3*$B$5+(1-$B$6)*(1-$B$7)^10*$B$2*$B$3*$B$5+(1-$B$6)*(1-$B$7)^9*$B$2*$B$3*$B$5+(1-$B$6)*(1-$B$7)^8*$B$2*$B$3*$B$5+(1-$B$6)*(1-$B$7)^7*$B$2*$B$3*$B$5+(1-$B$6)*(1-$B$7)^6*$B$2*$B$3*$B$5+(1-$B$6)*(1-$B$7)^5*$B$2*$B$3*$B$5+(1-$B$6)*(1-$B$7)^4*$B$2*$B$3*$B$5+(1-$B$6)*(1-$B$7)^3*$B$2*$B$3*$B$5+(1-$B$6)*(1-$B$7)^2*$B$2*$B$3*$B$5+(1-$B$6)*(1-$B$7)^1*$B$2*$B$3*$B$5+(1-$B$6)*$B$2*$B$3*$B$5 -> 8439.3771 | D36: =B36+C36 -> 11564.377 | E36: =D36+E35 -> 210239.29 | F36: =$B$2+(1-$B$6)*(1-$B$7)^25*$B$2+(1-$B$6)*(1-$B$7)^24*$B$2+(1-$B$6)*(1-$B$7)^23*$B$2+(1-$B$6)*(1-$B$7)^22*$B$2+(1-$B$6)*(1-$B$7)^21*$B$2+(1-$B$6)*(1-$B$7)^20*$B$2+(1-$B$6)*(1-$B$7)^19*$B$2+(1-$B$6)*(1-$B$7)^18*$B$2+(1-$B$6)*(1-$B$7)^17*$B$2+(1-$B$6)*(1-$B$7)^16*$B$2+(1-$B$6)*(1-$B$7)^15*$B$2+(1-$B$6)*(1-$B$7)^14*$B$2+(1-$B$6)*(1-$B$7)^13*$B$2+(1-$B$6)*(1-$B$7)^12*$B$2+(1-$B$6)*(1-$B$7)^11*$B$2+(1-$B$6)*(1-$B$7)^10*$B$2+(1-$B$6)*(1-$B$7)^9*$B$2+(1-$B$6)*(1-$B$7)^8*$B$2+(1-$B$6)*(1-$B$7)^7*$B$2+(1-$B$6)*(1-$B$7)^6*$B$2+(1-$B$6)*(1-$B$7)^5*$B$2+(1-$B$6)*(1-$B$7)^4*$B$2+(1-$B$6)*(1-$B$7)^3*$B$2+(1-$B$6)*(1-$B$7)^2*$B$2+(1-$B$6)*(1-$B$7)^1*$B$2+(1-$B$6)*$B$2 -> 725.15017
A37: 28 | B37: =$B$2*$B$3*$B$4 -> 3125 | C37: =(1-$B$6)*(1-$B$7)^26*$B$2*$B$3*$B$5+(1-$B$6)*(1-$B$7)^25*$B$2*$B$3*$B$5+(1-$B$6)*(1-$B$7)^24*$B$2*$B$3*$B$5+(1-$B$6)*(1-$B$7)^23*$B$2*$B$3*$B$5+(1-$B$6)*(1-$B$7)^22*$B$2*$B$3*$B$5+(1-$B$6)*(1-$B$7)^21*$B$2*$B$3*$B$5+(1-$B$6)*(1-$B$7)^20*$B$2*$B$3*$B$5+(1-$B$6)*(1-$B$7)^19*$B$2*$B$3*$B$5+(1-$B$6)*(1-$B$7)^18*$B$2*$B$3*$B$5+(1-$B$6)*(1-$B$7)^17*$B$2*$B$3*$B$5+(1-$B$6)*(1-$B$7)^16*$B$2*$B$3*$B$5+(1-$B$6)*(1-$B$7)^15*$B$2*$B$3*$B$5+(1-$B$6)*(1-$B$7)^14*$B$2*$B$3*$B$5+(1-$B$6)*(1-$B$7)^13*$B$2*$B$3*$B$5+(1-$B$6)*(1-$B$7)^12*$B$2*$B$3*$B$5+(1-$B$6)*(1-$B$7)^11*$B$2*$B$3*$B$5+(1-$B$6)*(1-$B$7)^10*$B$2*$B$3*$B$5+(1-$B$6)*(1-$B$7)^9*$B$2*$B$3*$B$5+(1-$B$6)*(1-$B$7)^8*$B$2*$B$3*$B$5+(1-$B$6)*(1-$B$7)^7*$B$2*$B$3*$B$5+(1-$B$6)*(1-$B$7)^6*$B$2*$B$3*$B$5+(1-$B$6)*(1-$B$7)^5*$B$2*$B$3*$B$5+(1-$B$6)*(1-$B$7)^4*$B$2*$B$3*$B$5+(1-$B$6)*(1-$B$7)^3*$B$2*$B$3*$B$5+(1-$B$6)*(1-$B$7)^2*$B$2*$B$3*$B$5+(1-$B$6)*(1-$B$7)^1*$B$2*$B$3*$B$5+(1-$B$6)*$B$2*$B$3*$B$5 -> 8665.8926 | D37: =B37+C37 -> 11790.893 | E37: =D37+E36 -> 222030.19 | F37: =$B$2+(1-$B$6)*(1-$B$7)^26*$B$2+(1-$B$6)*(1-$B$7)^25*$B$2+(1-$B$6)*(1-$B$7)^24*$B$2+(1-$B$6)*(1-$B$7)^23*$B$2+(1-$B$6)*(1-$B$7)^22*$B$2+(1-$B$6)*(1-$B$7)^21*$B$2+(1-$B$6)*(1-$B$7)^20*$B$2+(1-$B$6)*(1-$B$7)^19*$B$2+(1-$B$6)*(1-$B$7)^18*$B$2+(1-$B$6)*(1-$B$7)^17*$B$2+(1-$B$6)*(1-$B$7)^16*$B$2+(1-$B$6)*(1-$B$7)^15*$B$2+(1-$B$6)*(1-$B$7)^14*$B$2+(1-$B$6)*(1-$B$7)^13*$B$2+(1-$B$6)*(1-$B$7)^12*$B$2+(1-$B$6)*(1-$B$7)^11*$B$2+(1-$B$6)*(1-$B$7)^10*$B$2+(1-$B$6)*(1-$B$7)^9*$B$2+(1-$B$6)*(1-$B$7)^8*$B$2+(1-$B$6)*(1-$B$7)^7*$B$2+(1-$B$6)*(1-$B$7)^6*$B$2+(1-$B$6)*(1-$B$7)^5*$B$2+(1-$B$6)*(1-$B$7)^4*$B$2+(1-$B$6)*(1-$B$7)^3*$B$2+(1-$B$6)*(1-$B$7)^2*$B$2+(1-$B$6)*(1-$B$7)^1*$B$2+(1-$B$6)*$B$2 -> 743.27141
A38: 29 | B38: =$B$2*$B$3*$B$4 -> 3125 | C38: =(1-$B$6)*(1-$B$7)^27*$B$2*$B$3*$B$5+(1-$B$6)*(1-$B$7)^26*$B$2*$B$3*$B$5+(1-$B$6)*(1-$B$7)^25*$B$2*$B$3*$B$5+(1-$B$6)*(1-$B$7)^24*$B$2*$B$3*$B$5+(1-$B$6)*(1-$B$7)^23*$B$2*$B$3*$B$5+(1-$B$6)*(1-$B$7)^22*$B$2*$B$3*$B$5+(1-$B$6)*(1-$B$7)^21*$B$2*$B$3*$B$5+(1-$B$6)*(1-$B$7)^20*$B$2*$B$3*$B$5+(1-$B$6)*(1-$B$7)^19*$B$2*$B$3*$B$5+(1-$B$6)*(1-$B$7)^18*$B$2*$B$3*$B$5+(1-$B$6)*(1-$B$7)^17*$B$2*$B$3*$B$5+(1-$B$6)*(1-$B$7)^16*$B$2*$B$3*$B$5+(1-$B$6)*(1-$B$7)^15*$B$2*$B$3*$B$5+(1-$B$6)*(1-$B$7)^14*$B$2*$B$3*$B$5+(1-$B$6)*(1-$B$7)^13*$B$2*$B$3*$B$5+(1-$B$6)*(1-$B$7)^12*$B$2*$B$3*$B$5+(1-$B$6)*(1-$B$7)^11*$B$2*$B$3*$B$5+(1-$B$6)*(1-$B$7)^10*$B$2*$B$3*$B$5+(1-$B$6)*(1-$B$7)^9*$B$2*$B$3*$B$5+(1-$B$6)*(1-$B$7)^8*$B$2*$B$3*$B$5+(1-$B$6)*(1-$B$7)^7*$B$2*$B$3*$B$5+(1-$B$6)*(1-$B$7)^6*$B$2*$B$3*$B$5+(1-$B$6)*(1-$B$7)^5*$B$2*$B$3*$B$5+(1-$B$6)*(1-$B$7)^4*$B$2*$B$3*$B$5+(1-$B$6)*(1-$B$7)^3*$B$2*$B$3*$B$5+(1-$B$6)*(1-$B$7)^2*$B$2*$B$3*$B$5+(1-$B$6)*(1-$B$7)^1*$B$2*$B$3*$B$5+(1-$B$6)*$B$2*$B$3*$B$5 -> 8886.7453 | D38: =B38+C38 -> 12011.745 | E38: =D38+E37 -> 234041.93 | F38: =$B$2+(1-$B$6)*(1-$B$7)^27*$B$2+(1-$B$6)*(1-$B$7)^26*$B$2+(1-$B$6)*(1-$B$7)^25*$B$2+(1-$B$6)*(1-$B$7)^24*$B$2+(1-$B$6)*(1-$B$7)^23*$B$2+(1-$B$6)*(1-$B$7)^22*$B$2+(1-$B$6)*(1-$B$7)^21*$B$2+(1-$B$6)*(1-$B$7)^20*$B$2+(1-$B$6)*(1-$B$7)^19*$B$2+(1-$B$6)*(1-$B$7)^18*$B$2+(1-$B$6)*(1-$B$7)^17*$B$2+(1-$B$6)*(1-$B$7)^16*$B$2+(1-$B$6)*(1-$B$7)^15*$B$2+(1-$B$6)*(1-$B$7)^14*$B$2+(1-$B$6)*(1-$B$7)^13*$B$2+(1-$B$6)*(1-$B$7)^12*$B$2+(1-$B$6)*(1-$B$7)^11*$B$2+(1-$B$6)*(1-$B$7)^10*$B$2+(1-$B$6)*(1-$B$7)^9*$B$2+(1-$B$6)*(1-$B$7)^8*$B$2+(1-$B$6)*(1-$B$7)^7*$B$2+(1-$B$6)*(1-$B$7)^6*$B$2+(1-$B$6)*(1-$B$7)^5*$B$2+(1-$B$6)*(1-$B$7)^4*$B$2+(1-$B$6)*(1-$B$7)^3*$B$2+(1-$B$6)*(1-$B$7)^2*$B$2+(1-$B$6)*(1-$B$7)^1*$B$2+(1-$B$6)*$B$2 -> 760.93963
A39: 30 | B39: =$B$2*$B$3*$B$4 -> 3125 | C39: =(1-$B$6)*(1-$B$7)^28*$B$2*$B$3*$B$5+(1-$B$6)*(1-$B$7)^27*$B$2*$B$3*$B$5+(1-$B$6)*(1-$B$7)^26*$B$2*$B$3*$B$5+(1-$B$6)*(1-$B$7)^25*$B$2*$B$3*$B$5+(1-$B$6)*(1-$B$7)^24*$B$2*$B$3*$B$5+(1-$B$6)*(1-$B$7)^23*$B$2*$B$3*$B$5+(1-$B$6)*(1-$B$7)^22*$B$2*$B$3*$B$5+(1-$B$6)*(1-$B$7)^21*$B$2*$B$3*$B$5+(1-$B$6)*(1-$B$7)^20*$B$2*$B$3*$B$5+(1-$B$6)*(1-$B$7)^19*$B$2*$B$3*$B$5+(1-$B$6)*(1-$B$7)^18*$B$2*$B$3*$B$5+(1-$B$6)*(1-$B$7)^17*$B$2*$B$3*$B$5+(1-$B$6)*(1-$B$7)^16*$B$2*$B$3*$B$5+(1-$B$6)*(1-$B$7)^15*$B$2*$B$3*$B$5+(1-$B$6)*(1-$B$7)^14*$B$2*$B$3*$B$5+(1-$B$6)*(1-$B$7)^13*$B$2*$B$3*$B$5+(1-$B$6)*(1-$B$7)^12*$B$2*$B$3*$B$5+(1-$B$6)*(1-$B$7)^11*$B$2*$B$3*$B$5+(1-$B$6)*(1-$B$7)^10*$B$2*$B$3*$B$5+(1-$B$6)*(1-$B$7)^9*$B$2*$B$3*$B$5+(1-$B$6)*(1-$B$7)^8*$B$2*$B$3*$B$5+(1-$B$6)*(1-$B$7)^7*$B$2*$B$3*$B$5+(1-$B$6)*(1-$B$7)^6*$B$2*$B$3*$B$5+(1-$B$6)*(1-$B$7)^5*$B$2*$B$3*$B$5+(1-$B$6)*(1-$B$7)^4*$B$2*$B$3*$B$5+(1-$B$6)*(1-$B$7)^3*$B$2*$B$3*$B$5+(1-$B$6)*(1-$B$7)^2*$B$2*$B$3*$B$5+(1-$B$6)*(1-$B$7)^1*$B$2*$B$3*$B$5+(1-$B$6)*$B$2*$B$3*$B$5 -> 9102.0767 | D39: =B39+C39 -> 12227.077 | E39: =D39+E38 -> 246269.01 | F39: =$B$2+(1-$B$6)*(1-$B$7)^28*$B$2+(1-$B$6)*(1-$B$7)^27*$B$2+(1-$B$6)*(1-$B$7)^26*$B$2+(1-$B$6)*(1-$B$7)^25*$B$2+(1-$B$6)*(1-$B$7)^24*$B$2+(1-$B$6)*(1-$B$7)^23*$B$2+(1-$B$6)*(1-$B$7)^22*$B$2+(1-$B$6)*(1-$B$7)^21*$B$2+(1-$B$6)*(1-$B$7)^20*$B$2+(1-$B$6)*(1-$B$7)^19*$B$2+(1-$B$6)*(1-$B$7)^18*$B$2+(1-$B$6)*(1-$B$7)^17*$B$2+(1-$B$6)*(1-$B$7)^16*$B$2+(1-$B$6)*(1-$B$7)^15*$B$2+(1-$B$6)*(1-$B$7)^14*$B$2+(1-$B$6)*(1-$B$7)^13*$B$2+(1-$B$6)*(1-$B$7)^12*$B$2+(1-$B$6)*(1-$B$7)^11*$B$2+(1-$B$6)*(1-$B$7)^10*$B$2+(1-$B$6)*(1-$B$7)^9*$B$2+(1-$B$6)*(1-$B$7)^8*$B$2+(1-$B$6)*(1-$B$7)^7*$B$2+(1-$B$6)*(1-$B$7)^6*$B$2+(1-$B$6)*(1-$B$7)^5*$B$2+(1-$B$6)*(1-$B$7)^4*$B$2+(1-$B$6)*(1-$B$7)^3*$B$2+(1-$B$6)*(1-$B$7)^2*$B$2+(1-$B$6)*(1-$B$7)^1*$B$2+(1-$B$6)*$B$2 -> 778.16614
A40: 31 | B40: =$B$2*$B$3*$B$4 -> 3125 | C40: =(1-$B$6)*(1-$B$7)^29*$B$2*$B$3*$B$5+(1-$B$6)*(1-$B$7)^28*$B$2*$B$3*$B$5+(1-$B$6)*(1-$B$7)^27*$B$2*$B$3*$B$5+(1-$B$6)*(1-$B$7)^26*$B$2*$B$3*$B$5+(1-$B$6)*(1-$B$7)^25*$B$2*$B$3*$B$5+(1-$B$6)*(1-$B$7)^24*$B$2*$B$3*$B$5+(1-$B$6)*(1-$B$7)^23*$B$2*$B$3*$B$5+(1-$B$6)*(1-$B$7)^22*$B$2*$B$3*$B$5+(1-$B$6)*(1-$B$7)^21*$B$2*$B$3*$B$5+(1-$B$6)*(1-$B$7)^20*$B$2*$B$3*$B$5+(1-$B$6)*(1-$B$7)^19*$B$2*$B$3*$B$5+(1-$B$6)*(1-$B$7)^18*$B$2*$B$3*$B$5+(1-$B$6)*(1-$B$7)^17*$B$2*$B$3*$B$5+(1-$B$6)*(1-$B$7)^16*$B$2*$B$3*$B$5+(1-$B$6)*(1-$B$7)^15*$B$2*$B$3*$B$5+(1-$B$6)*(1-$B$7)^14*$B$2*$B$3*$B$5+(1-$B$6)*(1-$B$7)^13*$B$2*$B$3*$B$5+(1-$B$6)*(1-$B$7)^12*$B$2*$B$3*$B$5+(1-$B$6)*(1-$B$7)^11*$B$2*$B$3*$B$5+(1-$B$6)*(1-$B$7)^10*$B$2*$B$3*$B$5+(1-$B$6)*(1-$B$7)^9*$B$2*$B$3*$B$5+(1-$B$6)*(1-$B$7)^8*$B$2*$B$3*$B$5+(1-$B$6)*(1-$B$7)^7*$B$2*$B$3*$B$5+(1-$B$6)*(1-$B$7)^6*$B$2*$B$3*$B$5+(1-$B$6)*(1-$B$7)^5*$B$2*$B$3*$B$5+(1-$B$6)*(1-$B$7)^4*$B$2*$B$3*$B$5+(1-$B$6)*(1-$B$7)^3*$B$2*$B$3*$B$5+(1-$B$6)*(1-$B$7)^2*$B$2*$B$3*$B$5+(1-$B$6)*(1-$B$7)^1*$B$2*$B$3*$B$5+(1-$B$6)*$B$2*$B$3*$B$5 -> 9312.0248 | D40: =B40+C40 -> 12437.025 | E40: =D40+E39 -> 258706.03 | F40: =$B$2+(1-$B$6)*(1-$B$7)^29*$B$2+(1-$B$6)*(1-$B$7)^28*$B$2+(1-$B$6)*(1-$B$7)^27*$B$2+(1-$B$6)*(1-$B$7)^26*$B$2+(1-$B$6)*(1-$B$7)^25*$B$2+(1-$B$6)*(1-$B$7)^24*$B$2+(1-$B$6)*(1-$B$7)^23*$B$2+(1-$B$6)*(1-$B$7)^22*$B$2+(1-$B$6)*(1-$B$7)^21*$B$2+(1-$B$6)*(1-$B$7)^20*$B$2+(1-$B$6)*(1-$B$7)^19*$B$2+(1-$B$6)*(1-$B$7)^18*$B$2+(1-$B$6)*(1-$B$7)^17*$B$2+(1-$B$6)*(1-$B$7)^16*$B$2+(1-$B$6)*(1-$B$7)^15*$B$2+(1-$B$6)*(1-$B$7)^14*$B$2+(1-$B$6)*(1-$B$7)^13*$B$2+(1-$B$6)*(1-$B$7)^12*$B$2+(1-$B$6)*(1-$B$7)^11*$B$2+(1-$B$6)*(1-$B$7)^10*$B$2+(1-$B$6)*(1-$B$7)^9*$B$2+(1-$B$6)*(1-$B$7)^8*$B$2+(1-$B$6)*(1-$B$7)^7*$B$2+(1-$B$6)*(1-$B$7)^6*$B$2+(1-$B$6)*(1-$B$7)^5*$B$2+(1-$B$6)*(1-$B$7)^4*$B$2+(1-$B$6)*(1-$B$7)^3*$B$2+(1-$B$6)*(1-$B$7)^2*$B$2+(1-$B$6)*(1-$B$7)^1*$B$2+(1-$B$6)*$B$2 -> 794.96198
A41: 32 | B41: =$B$2*$B$3*$B$4 -> 3125 | C41: =(1-$B$6)*(1-$B$7)^30*$B$2*$B$3*$B$5+(1-$B$6)*(1-$B$7)^29*$B$2*$B$3*$B$5+(1-$B$6)*(1-$B$7)^28*$B$2*$B$3*$B$5+(1-$B$6)*(1-$B$7)^27*$B$2*$B$3*$B$5+(1-$B$6)*(1-$B$7)^26*$B$2*$B$3*$B$5+(1-$B$6)*(1-$B$7)^25*$B$2*$B$3*$B$5+(1-$B$6)*(1-$B$7)^24*$B$2*$B$3*$B$5+(1-$B$6)*(1-$B$7)^23*$B$2*$B$3*$B$5+(1-$B$6)*(1-$B$7)^22*$B$2*$B$3*$B$5+(1-$B$6)*(1-$B$7)^21*$B$2*$B$3*$B$5+(1-$B$6)*(1-$B$7)^20*$B$2*$B$3*$B$5+(1-$B$6)*(1-$B$7)^19*$B$2*$B$3*$B$5+(1-$B$6)*(1-$B$7)^18*$B$2*$B$3*$B$5+(1-$B$6)*(1-$B$7)^17*$B$2*$B$3*$B$5+(1-$B$6)*(1-$B$7)^16*$B$2*$B$3*$B$5+(1-$B$6)*(1-$B$7)^15*$B$2*$B$3*$B$5+(1-$B$6)*(1-$B$7)^14*$B$2*$B$3*$B$5+(1-$B$6)*(1-$B$7)^13*$B$2*$B$3*$B$5+(1-$B$6)*(1-$B$7)^12*$B$2*$B$3*$B$5+(1-$B$6)*(1-$B$7)^11*$B$2*$B$3*$B$5+(1-$B$6)*(1-$B$7)^10*$B$2*$B$3*$B$5+(1-$B$6)*(1-$B$7)^9*$B$2*$B$3*$B$5+(1-$B$6)*(1-$B$7)^8*$B$2*$B$3*$B$5+(1-$B$6)*(1-$B$7)^7*$B$2*$B$3*$B$5+(1-$B$6)*(1-$B$7)^6*$B$2*$B$3*$B$5+(1-$B$6)*(1-$B$7)^5*$B$2*$B$3*$B$5+(1-$B$6)*(1-$B$7)^4*$B$2*$B$3*$B$5+(1-$B$6)*(1-$B$7)^3*$B$2*$B$3*$B$5+(1-$B$6)*(1-$B$7)^2*$B$2*$B$3*$B$5+(1-$B$6)*(1-$B$7)^1*$B$2*$B$3*$B$5+(1-$B$6)*$B$2*$B$3*$B$5 -> 9516.7242 | D41: =B41+C41 -> 12641.724 | E41: =D41+E40 -> 271347.76 | F41: =$B$2+(1-$B$6)*(1-$B$7)^30*$B$2+(1-$B$6)*(1-$B$7)^29*$B$2+(1-$B$6)*(1-$B$7)^28*$B$2+(1-$B$6)*(1-$B$7)^27*$B$2+(1-$B$6)*(1-$B$7)^26*$B$2+(1-$B$6)*(1-$B$7)^25*$B$2+(1-$B$6)*(1-$B$7)^24*$B$2+(1-$B$6)*(1-$B$7)^23*$B$2+(1-$B$6)*(1-$B$7)^22*$B$2+(1-$B$6)*(1-$B$7)^21*$B$2+(1-$B$6)*(1-$B$7)^20*$B$2+(1-$B$6)*(1-$B$7)^19*$B$2+(1-$B$6)*(1-$B$7)^18*$B$2+(1-$B$6)*(1-$B$7)^17*$B$2+(1-$B$6)*(1-$B$7)^16*$B$2+(1-$B$6)*(1-$B$7)^15*$B$2+(1-$B$6)*(1-$B$7)^14*$B$2+(1-$B$6)*(1-$B$7)^13*$B$2+(1-$B$6)*(1-$B$7)^12*$B$2+(1-$B$6)*(1-$B$7)^11*$B$2+(1-$B$6)*(1-$B$7)^10*$B$2+(1-$B$6)*(1-$B$7)^9*$B$2+(1-$B$6)*(1-$B$7)^8*$B$2+(1-$B$6)*(1-$B$7)^7*$B$2+(1-$B$6)*(1-$B$7)^6*$B$2+(1-$B$6)*(1-$B$7)^5*$B$2+(1-$B$6)*(1-$B$7)^4*$B$2+(1-$B$6)*(1-$B$7)^3*$B$2+(1-$B$6)*(1-$B$7)^2*$B$2+(1-$B$6)*(1-$B$7)^1*$B$2+(1-$B$6)*$B$2 -> 811.33793
...

Sheet Gráfico 36 Meses
A1: Mes | B1: Ganancia por Activaciones (MXN) | C1: Ganancia Residual 10% (con Degradación) (MXN) | D1: Ganancia Total por Mes (MXN) | E1: Ganancia Acumulada (MXN)
A2: ='Proyección 36 Meses'!A10 -> 1 | B2: ='Proyección 36 Meses'!B10 -> 3125 | C2: ='Proyección 36 Meses'!C10 -> 0 | D2: ='Proyección 36 Meses'!D10 -> 3125 | E2: ='Proyección 36 Meses'!E10 -> 3125
A3: ='Proyección 36 Meses'!A11 -> 2 | B3: ='Proyección 36 Meses'!B11 -> 3125 | C3: ='Proyección 36 Meses'!C11 -> 437.5 | D3: ='Proyección 36 Meses'!D11 -> 3562.5 | E3: ='Proyección 36 Meses'!E11 -> 6687.5
A4: ='Proyección 36 Meses'!A12 -> 3 | B4: ='Proyección 36 Meses'!B12 -> 3125 | C4: ='Proyección 36 Meses'!C12 -> 864.0625 | D4: ='Proyección 36 Meses'!D12 -> 3989.0625 | E4: ='Proyección 36 Meses'!E12 -> 10676.562
A5: ='Proyección 36 Meses'!A13 -> 4 | B5: ='Proyección 36 Meses'!B13 -> 3125 | C5: ='Proyección 36 Meses'!C13 -> 1279.9609 | D5: ='Proyección 36 Meses'!D13 -> 4404.9609 | E5: ='Proyección 36 Meses'!E13 -> 15081.523
A6: ='Proyección 36 Meses'!A14 -> 5 | B6: ='Proyección 36 Meses'!B14 -> 3125 | C6: ='Proyección 36 Meses'!C14 -> 1685.4619 | D6: ='Proyección 36 Meses'!D14 -> 4810.4619 | E6: ='Proyección 36 Meses'!E14 -> 19891.985
A7: ='Proyección 36 Meses'!A15 -> 6 | B7: ='Proyección 36 Meses'!B15 -> 3125 | C7: ='Proyección 36 Meses'!C15 -> 2080.8254 | D7: ='Proyección 36 Meses'!D15 -> 5205.8254 | E7: ='Proyección 36 Meses'!E15 -> 25097.811
A8: ='Proyección 36 Meses'!A16 -> 7 | B8: ='Proyección 36 Meses'!B16 -> 3125 | C8: ='Proyección 36 Meses'!C16 -> 2466.3047 | D8: ='Proyección 36 Meses'!D16 -> 5591.3047 | E8: ='Proyección 36 Meses'!E16 -> 30689.115
A9: ='Proyección 36 Meses'!A17 -> 8 | B9: ='Proyección 36 Meses'!B17 -> 3125 | C9: ='Proyección 36 Meses'!C17 -> 2842.1471 | D9: ='Proyección 36 Meses'!D17 -> 5967.1471 | E9: ='Proyección 36 Meses'!E17 -> 36656.263
A10: ='Proyección 36 Meses'!A18 -> 9 | B10: ='Proyección 36 Meses'!B18 -> 3125 | C10: ='Proyección 36 Meses'!C18 -> 3208.5934 | D10: ='Proyección 36 Meses'!D18 -> 6333.5934 | E10: ='Proyección 36 Meses'!E18 -> 42989.856
A11: ='Proyección 36 Meses'!A19 -> 10 | B11: ='Proyección 36 Meses'!B19 -> 3125 | C11: ='Proyección 36 Meses'!C19 -> 3565.8786 | D11: ='Proyección 36 Meses'!D19 -> 6690.8786 | E11: ='Proyección 36 Meses'!E19 -> 49680.735
A12: ='Proyección 36 Meses'!A20 -> 11 | B12: ='Proyección 36 Meses'!B20 -> 3125 | C12: ='Proyección 36 Meses'!C20 -> 3914.2316 | D12: ='Proyección 36 Meses'!D20 -> 7039.2316 | E12: ='Proyección 36 Meses'!E20 -> 56719.966
A13: ='Proyección 36 Meses'!A21 -> 12 | B13: ='Proyección 36 Meses'!B21 -> 3125 | C13: ='Proyección 36 Meses'!C21 -> 4253.8758 | D13: ='Proyección 36 Meses'!D21 -> 7378.8758 | E13: ='Proyección 36 Meses'!E21 -> 64098.842
... A37: ='Proyección 36 Meses'!A45 -> 36 | B37: ='Proyección 36 Meses'!B45 -> 3125 | C37: ='Proyección 36 Meses'!C45 -> 10285.61 | D37: ='Proyección 36 Meses'!D45 -> 13410.61 | E37: ='Proyección 36 Meses'!E45 -> 323861.2
